<?xml version="1.0"?>
<robot name="diff_drive_robot">

  <!--............................... DEFAULT DRIVER PLUGINS ..................................... -->
    <gazebo>
        <plugin filename="ignition-gazebo-sensors-system" name="ignition::gazebo::systems::Sensors">
            <render_engine>ogre2</render_engine>
        </plugin>

        <plugin filename="ignition-gazebo-imu-system" name="ignition::gazebo::systems::Imu">
        </plugin>

        <plugin filename="ignition-gazebo-joint-state-publisher-system" name="ignition::gazebo::systems::JointStatePublisher">
        </plugin>
    </gazebo>


    <!--............................... MATERIALS ..................................... -->
    <material name="blue">
        <color rgba="0 0.4 0.5 1"/>
    </material>
    <material name="invisible">
        <color rgba="0.0 0.0 0.0 0.0"/>
    </material>

      <!--............................... LINKS ..................................... -->

    <!-- camera link -->
    <link name="camera_link_optical"></link>

    <!--  mu link -->
    <link name="imu_link"></link>
    
    <!-- base link -->
    <link name="base_link"/>

    <!-- Chassis link -->
    <link name="chassis_link">
        <visual>
            <origin xyz="0 0 0" rpy="0 0 0"/>
            <geometry>
                <box size="0.2 0.12 0.01"/>
            </geometry>
            <material name="red">
                <color rgba="1 0 0 1"/>
            </material>
        </visual>
        <collision>
            <origin xyz="0 0 0" rpy="0 0 0"/>
            <geometry>
                <box size="0.2 0.12 0.01"/>
            </geometry>
        </collision>
        <inertial>
            <mass value="0.4"/>
            <inertia ixx="0.00048333" iyy="0.0013367" izz="0.0018133" ixy="0" ixz="0" iyz="0"/>
        </inertial>
    </link>
    
    <!-- Wheel links -->
    <link name="front_right_wheel_link">
        <visual>
            <origin xyz="0 0 0" rpy="1.5708 0 0"/>
            <geometry>
                <cylinder radius="0.03" length="0.01"/>
            </geometry>
            <material name="blue"/>
        </visual>
        <collision>
            <origin xyz="0 0 0" rpy="1.5708 0 0"/>
            <geometry>
                <cylinder radius="0.03" length="0.01"/>
            </geometry>
        </collision>
        <inertial>
            <mass value="0.2"/>
            <inertia ixx="0.00004667" iyy="0.00004667" izz="0.00009" ixy="0" ixz="0" iyz="0"/>
        </inertial>
    </link>

    <link name="front_left_wheel_link">
        <visual>
            <origin xyz="0 0 0" rpy="1.5708 0 0"/>
            <geometry>
                <cylinder radius="0.03" length="0.01"/>
            </geometry>
            <material name="blue"/>
        </visual>
        <collision>
            <origin xyz="0 0 0" rpy="1.5708 0 0"/>
            <geometry>
                <cylinder radius="0.03" length="0.01"/>
            </geometry>
        </collision>
        <inertial>
            <mass value="0.2"/>
            <inertia ixx="0.00004667" iyy="0.00004667" izz="0.00009" ixy="0" ixz="0" iyz="0"/>
        </inertial>
    </link>

    <link name="rear_right_wheel_link">
        <visual>
            <origin xyz="0 0 0" rpy="1.5708 0 0"/>
            <geometry>
                <cylinder radius="0.03" length="0.01"/>
            </geometry>
            <material name="blue"/>
        </visual>
        <collision>
            <origin xyz="0 0 0" rpy="1.5708 0 0"/>
            <geometry>
                <cylinder radius="0.03" length="0.01"/>
            </geometry>
        </collision>
        <inertial>
            <mass value="0.2"/>
            <inertia ixx="0.00004667" iyy="0.00004667" izz="0.00009" ixy="0" ixz="0" iyz="0"/>
        </inertial>
    </link>

    <link name="rear_left_wheel_link">
        <visual>
            <origin xyz="0 0 0" rpy="1.5708 0 0"/>
            <geometry>
                <cylinder radius="0.03" length="0.01"/>
            </geometry>
            <material name="blue"/>
        </visual>
        <collision>
            <origin xyz="0 0 0" rpy="1.5708 0 0"/>
            <geometry>
                <cylinder radius="0.03" length="0.01"/>
            </geometry>
        </collision>
        <inertial>
            <mass value="0.2"/>
            <inertia ixx="0.00004667" iyy="0.00004667" izz="0.00009" ixy="0" ixz="0" iyz="0"/>
        </inertial>
    </link>

   <!-- Virtual rear wheel -->
    <link name="virtual_rear_wheel">
      <visual>
        <origin xyz="-0.06 0.065 0" rpy="0 0 0"/>
        <geometry>
          <cylinder length="0.01" radius="0.03"/>
        </geometry>
        <material name="invisible"/>
      </visual>
        <inertial>
            <mass value="0.2"/>
            <inertia ixx="0.00004667" iyy="0.00004667" izz="0.00009" ixy="0" ixz="0" iyz="0"/>
        </inertial>
    </link>

    <link name="virtual_front_wheel">
        <visual>
            <origin xyz="0 0 0" rpy="1.5708 0 1.5708"/>
            <geometry>
                <cylinder length="0.01" radius="0.03"/>
            </geometry>
            <material name="invisible"/>
        </visual>
        <inertial>
            <mass value="0.2"/>
            <inertia ixx="0.00004667" iyy="0.00004667" izz="0.00009" ixy="0" ixz="0" iyz="0"/>
        </inertial>
    </link>

    <!-- Joints -->
    <joint name="joint_base_chassis" type="fixed">
        <parent link="base_link"/>
        <child link="chassis_link"/>
        <origin xyz="0 0 0.03" rpy="0 0 0"/>
    </joint>    

    <joint name="joint_chassis_front_right_wheel" type="continuous">
        <parent link="chassis_link"/>
        <child link="front_right_wheel_link"/>
        <origin xyz="0.06 0.065 0" rpy="0 0 0"/>
        <axis xyz="0 1 0"/>
    </joint>
    
    <joint name="joint_chassis_front_left_wheel" type="continuous">
        <parent link="chassis_link"/>
        <child link="front_left_wheel_link"/>
        <origin xyz="0.06 -0.065 0" rpy="0 0 0"/>
        <axis xyz="0 1 0"/>
    </joint>
    
    <joint name="joint_chassis_rear_right_wheel" type="continuous">
        <parent link="chassis_link"/>
        <child link="rear_right_wheel_link"/>
        <origin xyz="-0.06 0.065 0" rpy="0 0 0"/>
        <axis xyz="0 1 0"/>
    </joint>
    
    <joint name="joint_chassis_rear_left_wheel" type="continuous">
        <parent link="chassis_link"/>
        <child link="rear_left_wheel_link"/>
        <origin xyz="-0.06 -0.065 0" rpy="0 0 0"/>
        <axis xyz="0 1 0"/>
    </joint>

    <joint name="virtual_rear_wheel_joint" type="continuous">
      <parent link="chassis_link"/>
      <child link="virtual_rear_wheel"/>
      <origin xyz="-0.06 0 0" rpy="0 0 1.5708"/>
      <axis xyz="1 0 0"/>
      <limit effort="100.0" velocity="100.0"/>
      <dynamics damping="0.2"/>
    </joint>

    <joint name="virtual_front_wheel_joint" type="revolute">
        <parent link="chassis_link"/> <!-- Corrected the link name -->
        <child link="virtual_front_wheel"/>
        <origin xyz="0.3 0 -0.15"/> <!-- Replace with your actual values -->
        <axis xyz="0 0 1"/>
        <limit lower="-0.4" upper="0.4" effort="100.0" velocity="0.0"/>
        <dynamics damping="0.2"/>
    </joint>

    <joint name="camera_optical_joint" type="fixed">
        <origin xyz="0 0 0" rpy="-1.571 0 -1.571" />
         <parent link="chassis_link"/>
        <child link="camera_link_optical" />
    </joint>
    
    <joint name="imu_joint" type="fixed">
        <parent link="chassis_link" />
        <child link="imu_link" />
        <origin xyz="0 0 1.2" rpy="0 0 0" />
    </joint>

    <ros2_control name="IgnitionSystem" type="system">
        <hardware>
            <plugin>ign_ros2_control/IgnitionSystem</plugin>
            <param name="calculate_dynamics">true</param>
        </hardware>
        <joint name="virtual_front_wheel_joint">
            <command_interface name="position"/>
            <state_interface name="position"/>
        </joint>
        <joint name="virtual_rear_wheel_joint">
            <command_interface name="velocity"/>
            <state_interface name="velocity"/>
            <state_interface name="position"/>
        </joint>
    </ros2_control>

    <!--............................... IMU PLUGIN ..................................... -->

    <gazebo reference="imu_frame">
        <sensor name="imu" type="imu">
            <always_on>true</always_on>
            <update_rate>5</update_rate>
            <plugin name="imu_plugin" filename="libgazebo_ros_imu_sensor.so">
                <ros>
                    <remapping>~/out:=imu</remapping>
                </ros>
            </plugin>
        </sensor>
    </gazebo>


   <!-- ........................... CAMERA PLUGIN ................................... -->
       <gazebo reference="camera_link">
        <sensor type="depth" name="my_camera">
            <update_rate>20</update_rate>
            <visualize>true</visualize>
            <camera name="cam">
                <horizontal_fov>1.3962634</horizontal_fov>
                <image>
                    <width>640</width>
                    <height>480</height>
                    <format>R8B8G8</format>
                </image>
                <clip>
                    <near>0.02</near>
                    <far>300</far>
                </clip>
                <noise>
                    <type>gaussian</type>
                    <mean>0.0</mean>
                    <stddev>0.007</stddev>
                </noise>
            </camera>
            <plugin name="camera_plugin" filename="libgazebo_ros_openni_kinect.so">
                <baseline>0.2</baseline>
                <alwaysOn>true</alwaysOn>
                <updateRate>0.0</updateRate>
                <cameraName>camera_ir</cameraName>
                <imageTopicName>/camera/color/image_raw</imageTopicName>
                <cameraInfoTopicName>/camera/color/camera_info</cameraInfoTopicName>
                <depthImageTopicName>/camera/depth/image_raw</depthImageTopicName>
                <depthImageCameraInfoTopicName>/camera/depth/camera_info</depthImageCameraInfoTopicName>
                <pointCloudTopicName>/camera/depth/points</pointCloudTopicName>
                <frameName>camera_link</frameName>
                <pointCloudCutoff>0.5</pointCloudCutoff>
                <pointCloudCutoffMax>3.0</pointCloudCutoffMax>
                <distortionK1>0</distortionK1>
                <distortionK2>0</distortionK2>
                <distortionK3>0</distortionK3>
                <distortionT1>0</distortionT1>
                <distortionT2>0</distortionT2>
                <CxPrime>0</CxPrime>
                <Cx>0</Cx>
                <Cy>0</Cy>
                <focalLength>0</focalLength>
                <hackBaseline>0</hackBaseline>
            </plugin>
        </sensor>
    </gazebo>

    <gazebo>
        <plugin filename="ign_ros2_control-system" name="ign_ros2_control::IgnitionROS2ControlPlugin">
            <robot_param>robot_description</robot_param>
            <robot_param_node>robot_state_publisher</robot_param_node>
            <parameters>/home/prashun/ros2_ws/src/uno/config/controller.yaml</parameters>
        </plugin>
    </gazebo>
</robot>
