<?xml version='1.0'?>
<robot name="diff_drive_robot">
	
	<material name="blue">
		<color rgba="0 0.4 0.5 1"/>
	</material>
	
	<!--dummy link-->
	<link name="base_link"/>
	
	<!--chassis link-->
	<link name="chassis-link">
		<visual>
			<origin xyz="0 0 0" rpy="0 0 0" />
			<geometry>
				<box size="0.2 0.12 .01" />
			</geometry>
			<material name="red">
				<color rgba="1 0 0 1"/>
			</material>		
		</visual>
		<collision>
			<origin xyz="0 0 0" rpy="0 0 0" />
			<geometry>
				<box size="0.2 0.12 .01" />
			</geometry>
		</collision>
		<inertial>
			<mass value="0.4" />
			<inertia ixx="0.00048333" iyy="0.0013367" izz="0.0018133"
			ixy="0" ixz="0" iyz="0"/>
		</inertial>
	</link>
	
	<link name="front-right-wheel-link">
		<visual>
			<origin xyz="0 0 0" rpy="1.57079 0 0" />
			<geometry>
				<cylinder radius ="0.03"  length="0.01" />
			</geometry>
			<material name="blue" />
		</visual>
		<collision>
			<origin xyz="0 0 0" rpy="1.57079 0 0" />
			<geometry>
				<cylinder radius ="0.03"  length="0.01" />
			</geometry>
		</collision>
		<inertial>
			<origin xyz="0 0 0" rpy="1.57079 0 0" />
			<mass value="0.2" />
			<inertia ixx="0.00004667" iyy="0.00004667" izz="0.00009"
			ixy="0" ixz="0" iyz="0"/>
		</inertial>
	</link>
	
	<link name="front-left-wheel-link">
		<visual>
			<origin xyz="0 0 0" rpy="1.57079 0 0" />
			<geometry>
				<cylinder radius ="0.03"  length="0.01" />
			</geometry>
			<material name="blue" />
		</visual>
		<collision>
			<origin xyz="0 0 0" rpy="1.57079 0 0" />
			<geometry>
				<cylinder radius ="0.03"  length="0.01" />
			</geometry>
		</collision>
		<inertial>
			<origin xyz="0 0 0" rpy="1.57079 0 0" />
			<mass value="0.2" />
			<inertia ixx="0.00004667" iyy="0.00004667" izz="0.00009"
			ixy="0" ixz="0" iyz="0"/>
		</inertial>
	</link>
	
	<link name="rear-right-wheel-link">
		<visual>
			<origin xyz="0 0 0" rpy="1.57079 0 0" />
			<geometry>
				<cylinder radius ="0.03"  length="0.01" />
			</geometry>
			<material name="blue" />
		</visual>
		<collision>
			<origin xyz="0 0 0" rpy="1.57079 0 0" />
			<geometry>
				<cylinder radius ="0.03"  length="0.01" />
			</geometry>
		</collision>
		<inertial>
			<origin xyz="0 0 0" rpy="1.57079 0 0" />
			<mass value="0.2" />
			<inertia ixx="0.00004667" iyy="0.00004667" izz="0.00009"
			ixy="0" ixz="0" iyz="0"/>
		</inertial>
	</link>
	
	<link name="rear-left-wheel-link">
		<visual>
			<origin xyz="0 0 0" rpy="1.57079 0 0" />
			<geometry>
				<cylinder radius ="0.03"  length="0.01" />
			</geometry>
			<material name="blue" />
		</visual>	
		<collision>
			<origin xyz="0 0 0" rpy="1.57079 0 0" />
			<geometry>
				<cylinder radius ="0.03"  length="0.01" />
			</geometry>
		</collision>	
		<inertial>
			<origin xyz="0 0 0" rpy="1.57079 0 0" />
			<mass value="0.2" />
			<inertia ixx="0.00004667" iyy="0.00004667" izz="0.00009"
			ixy="0" ixz="0" iyz="0"/>
		</inertial>
	</link>
	
	<joint name="joint-base-chassis" type="fixed">
		<parent link="base_link"/>
		<child link="chassis-link"/>
		<origin xyz="0 0 0.03" rpy="0 0 0" />
	</joint>	
	
	<joint name="joint-chassis-front-right-wheel" type="continuous">
		<parent link="chassis-link"/>
		<child link="front-right-wheel-link"/>
		<origin xyz="0.06 0.065 0" rpy="0 0 0" />
		<axis xyz="0 1 0" />
	</joint>
	
	<joint name="joint-chassis-front-left-wheel" type="continuous">
		<parent link="chassis-link"/>
		<child link="front-left-wheel-link"/>
		<origin xyz="0.06 -0.065 0" rpy="0 0 0" />
		<axis xyz="0 1 0" />
	</joint>
	
	<joint name="joint-chassis-rear-right-wheel" type="continuous">
		<parent link="chassis-link"/>
		<child link="rear-right-wheel-link"/>
		<origin xyz="-0.06 0.065 0" rpy="0 0 0" />
		<axis xyz="0 1 0" />
	</joint>
	
	<joint name="joint-chassis-rear-left-wheel" type="continuous">
		<parent link="chassis-link"/>
		<child link="rear-left-wheel-link"/>
		<origin xyz="-0.06 -0.065 0" rpy="0 0 0" />
		<axis xyz="0 1 0" />
	</joint>

	<ros2_control name="IgnitionSystem" type="system">
		<hardware>
          <plugin>ign_ros2_control/IgnitionSystem</plugin>
          <param name="calculate_dynamics">true</param>
        </hardware>
		<joint name="joint-chassis-front-right-wheel">
			<command_interface name="velocity">
				<param name="min">-10</param>
				<param name="max">10</param>
			</command_interface>
			<state_interface name="position">
				<param name="initial_value">1.0</param>
			</state_interface>
			<state_interface name="velocity"/>
			<state_interface name="effort"/>
		</joint>
		
		<joint name="joint-chassis-front-left-wheel"> <!-- Changed name for uniqueness -->
			<command_interface name="velocity">
				<param name="min">-10</param>
				<param name="max">10</param>
			</command_interface>
			<state_interface name="position">
				<param name="initial_value">1.0</param>
			</state_interface>
			<state_interface name="velocity"/>
			<state_interface name="effort"/>
		</joint>
	</ros2_control>

    
    <gazebo>
        <plugin filename="ign_ros2_control-system" name="ign_ros2_control::IgnitionROS2ControlPlugin">
            <robot_param>robot_description</robot_param>
            <robot_param_node>robot_state_publisher</robot_param_node>
            <parameters>/home/prashun/ros2_ws/src/uno/config/controller.yaml</parameters>
        </plugin>
    </gazebo>

</robot>