<?xml version="1.0"?>
<robot name="diff_drive_robot">

     <!--............................... SENSOR PLUGINS ..................................... -->
    <gazebo>
         <plugin filename="ignition-gazebo-sensors-system" name="ignition::gazebo::systems::Sensors">
            <render_engine>ogre2</render_engine>
        </plugin>
        <plugin filename="ignition-gazebo-imu-system" name="ignition::gazebo::systems::Imu">
        </plugin>
          <plugin filename="ignition-gazebo-joint-state-publisher-system" name="ignition::gazebo::systems::JointStatePublisher">
      </plugin>
    </gazebo>
    <!--............................... MATERIALS ..................................... -->
    <material name="blue">
        <color rgba="0 0.4 0.5 1"/>
    </material>
    <material name="invisible">
        <color rgba="0.0 0.0 0.0 0.0"/>
    </material>

    <!--............................... LINKS ..................................... -->

    <!-- camera link -->
    <link name="camera_link_optical"></link>

    <!--  imu link -->
    <link name="imu_link"></link>
    
   
    <!-- This first link called "world" is empty -->
    <link name="world"></link>
  
    <!-- baselink -->
    <link name="base_link"></link>

    <!-- Chassis link -->
    <link name="chassis_link">
        <visual>
            <origin xyz="0 0 0" rpy="0 0 0"/>
            <geometry>
                <box size="0.2 0.12 0.01"/>
            </geometry>
            <material name="red">
                <color rgba="1 0 0 1"/>
            </material>
        </visual>
        <collision>
            <origin xyz="0 0 0" rpy="0 0 0"/>
            <geometry>
                <box size="0.2 0.12 0.01"/>
            </geometry>
        </collision>
        <inertial>
            <mass value="0.4"/>
            <inertia ixx="0.00048333" iyy="0.0013367" izz="0.0018133" ixy="0" ixz="0" iyz="0"/>
        </inertial>
    </link>
    
    <!-- Wheel links -->
    <link name="front_right_wheel_link">
        <visual>
            <origin xyz="0 0 0" rpy="1.5708 0 0"/>
            <geometry>
                <cylinder radius="0.03" length="0.01"/>
            </geometry>
            <material name="blue"/>
        </visual>
        <collision>
            <origin xyz="0 0 0" rpy="1.5708 0 0"/>
            <geometry>
                <cylinder radius="0.03" length="0.01"/>
            </geometry>
        </collision>
        <inertial>
            <mass value="0.2"/>
            <inertia ixx="0.00004667" iyy="0.00004667" izz="0.00009" ixy="0" ixz="0" iyz="0"/>
        </inertial>
    </link>

    <link name="front_left_wheel_link">
        <visual>
            <origin xyz="0 0 0" rpy="1.5708 0 0"/>
            <geometry>
                <cylinder radius="0.03" length="0.01"/>
            </geometry>
            <material name="blue"/>
        </visual>
        <collision>
            <origin xyz="0 0 0" rpy="1.5708 0 0"/>
            <geometry>
                <cylinder radius="0.03" length="0.01"/>
            </geometry>
        </collision>
        <inertial>
            <mass value="0.2"/>
            <inertia ixx="0.00004667" iyy="0.00004667" izz="0.00009" ixy="0" ixz="0" iyz="0"/>
        </inertial>
    </link>

    <link name="rear_right_wheel_link">
        <visual>
            <origin xyz="0 0 0" rpy="1.5708 0 0"/>
            <geometry>
                <cylinder radius="0.03" length="0.01"/>
            </geometry>
            <material name="blue"/>
        </visual>
        <collision>
            <origin xyz="0 0 0" rpy="1.5708 0 0"/>
            <geometry>
                <cylinder radius="0.03" length="0.01"/>
            </geometry>
        </collision>
        <inertial>
            <mass value="0.2"/>
            <inertia ixx="0.00004667" iyy="0.00004667" izz="0.00009" ixy="0" ixz="0" iyz="0"/>
        </inertial>
    </link>

    <link name="rear_left_wheel_link">
        <visual>
            <origin xyz="0 0 0" rpy="1.5708 0 0"/>
            <geometry>
                <cylinder radius="0.03" length="0.01"/>
            </geometry>
            <material name="blue"/>
        </visual>
        <collision>
            <origin xyz="0 0 0" rpy="1.5708 0 0"/>
            <geometry>
                <cylinder radius="0.03" length="0.01"/>
            </geometry>
        </collision>
        <inertial>
            <mass value="0.2"/>
            <inertia ixx="0.00004667" iyy="0.00004667" izz="0.00009" ixy="0" ixz="0" iyz="0"/>
        </inertial>
    </link>

   <!-- Virtual rear wheel -->
    <link name="virtual_rear_wheel">
          <visual>
            <origin xyz="0 0 0" rpy="0 1.5708 0"/>
            <geometry>
                <cylinder radius="0.03" length="0.01"/>
            </geometry>
            <material name="invisible"/>
        </visual>
        <collision>
            <origin xyz="0 0 0" rpy="0 1.5708 0"/>
            <geometry>
                <cylinder radius="0.03" length="0.01"/>
            </geometry>
        </collision>
        <inertial>
            <mass value="0.2"/>
            <inertia ixx="0.00004667" iyy="0.00004667" izz="0.00009" ixy="0" ixz="0" iyz="0"/>
        </inertial>
    </link>

    <link name="virtual_front_wheel">
        <visual>
            <origin xyz="0 -0.12 0" rpy="0 1.5708 0"/>
            <geometry>
                <cylinder radius="0.03" length="0.01"/>
            </geometry>
            <material name="invisible"/>
        </visual>
        <collision>
            <origin xyz="0 0 0" rpy="0 1.5708 0"/>
            <geometry>
                <cylinder radius="0.03" length="0.01"/>
            </geometry>
        </collision>
        <inertial>
            <mass value="0.2"/>
            <inertia ixx="0.00004667" iyy="0.00004667" izz="0.00009" ixy="0" ixz="0" iyz="0"/>
        </inertial>
    </link>

    <!-- Joints -->

    <joint name="base_joint" type="fixed">
        <origin xyz="1.5 1.0 0" rpy="0 0 0"/>
        <parent link="world"/>
        <child link="base_link"/>        
    </joint>

    <joint name="joint_base_chassis" type="fixed">
        <parent link="base_link"/>
        <child link="chassis_link"/>
        <origin xyz="0 0 0" rpy="0 0 0"/>
    </joint>    

    <joint name="joint_chassis_front_right_wheel" type="continuous">
        <parent link="chassis_link"/>
        <child link="front_right_wheel_link"/>
        <origin xyz="0.06 0.065 0" rpy="0 0 0"/>
        <axis xyz="0 1 0"/>
    </joint>
    
    <joint name="joint_chassis_front_left_wheel" type="continuous">
        <parent link="chassis_link"/>
        <child link="front_left_wheel_link"/>
        <origin xyz="0.06 -0.065 0" rpy="0 0 0"/>
        <axis xyz="0 1 0"/>
    </joint>
    
    <joint name="joint_chassis_rear_right_wheel" type="continuous">
        <parent link="chassis_link"/>
        <child link="rear_right_wheel_link"/>
        <origin xyz="-0.06 0.065 0" rpy="0 0 0"/>
        <axis xyz="0 1 0"/>
    </joint>
    
    <joint name="joint_chassis_rear_left_wheel" type="continuous">
        <parent link="chassis_link"/>
        <child link="rear_left_wheel_link"/>
        <origin xyz="-0.06 -0.065 0" rpy="0 0 0"/>
        <axis xyz="0 1 0"/>
    </joint>

    <joint name="virtual_rear_wheel_joint" type="continuous">
      <parent link="chassis_link"/>
      <child link="virtual_rear_wheel"/>
      <origin xyz="-0.06 0 0" rpy="0 0 1.5708"/>
      <axis xyz="1 0 0"/>
      <limit effort="100.0" velocity="100.0"/>
      <dynamics damping="0.2"/>
    </joint>

    <joint name="virtual_front_wheel_joint" type="revolute">
        <parent link="chassis_link"/> <!-- Corrected the link name -->
        <child link="virtual_front_wheel"/>
        <origin xyz="-0.06 0 0" rpy="0 0 1.5708"/>
        <axis xyz="0 0 1"/>
        <limit lower="-0.4" upper="0.4" effort="100.0" velocity="0.0"/>
        <dynamics damping="0.2"/>
    </joint>

    <joint name="camera_optical_joint" type="fixed">
        <origin xyz="0 0 0" rpy="-1.571 0 -1.571" />
         <parent link="chassis_link"/>
        <child link="camera_link_optical" />
    </joint>
    
    <joint name="imu_joint" type="fixed">
        <parent link="chassis_link" />
        <child link="imu_link" />
        <origin xyz="0 0 1.2" rpy="0 0 0" />
    </joint>

<!--............................... GAZEBO DRIVER ..................................... -->
    <gazebo>
        <plugin
            filename="libignition-gazebo-diff-drive-system.so"
            name="ignition::gazebo::systems::DiffDrive">
            <left_joint>joint_chassis_front_left_wheel</left_joint>
            <right_joint>joint_chassis_front_right_wheel</right_joint>
            <wheel_separation>0.2</wheel_separation>
            <wheel_radius>0.03</wheel_radius>
            <odom_publish_frequency>1</odom_publish_frequency>
            <topic>cmd_vel</topic>
        </plugin>
    </gazebo>

    <!--............................... CONTROLLER .................................... -->

    <ros2_control name="IgnitionSystem" type="system">
        <hardware>
            <plugin>ign_ros2_control/IgnitionSystem</plugin>
            <param name="calculate_dynamics">true</param>
        </hardware>
        <joint name="joint_chassis_front_left_wheel">
            <command_interface name="velocity"/>
            <state_interface name="position"/>
            <state_interface name="velocity"/>
        </joint>
        <joint name="joint_chassis_front_right_wheel">
            <command_interface name="velocity"/>
            <state_interface name="velocity"/>
            <state_interface name="position"/>
        </joint>
    </ros2_control>

    <!--............................... IMU PLUGIN ..................................... -->

    <gazebo reference="imu_frame">
        <sensor name="imu" type="imu">
            <always_on>true</always_on>
            <update_rate>5</update_rate>
            <visualize>true</visualize>
            <topic>imu</topic>
            <plugin name="imu_plugin" filename="libgazebo_ros_imu_sensor.so">
                <ros>
                    <remapping>~/out:=imu</remapping>
                </ros>
            </plugin>
        </sensor>
    </gazebo>


   <!-- ........................... CAMERA PLUGIN ................................... -->
       <gazebo reference="camera_link">
        <sensor type="depth" name="kinect_camera">
            <topic>rgbd_camera/image</topic>
            <update_rate>20</update_rate>
            <visualize>true</visualize>
            <camera_info_topic>rgbd_camera/camera_info</camera_info_topic>
            <camera name="cam">
                <horizontal_fov>1.3962634</horizontal_fov>
                <image>
                    <width>640</width>
                    <height>480</height>
                    <format>R8B8G8</format>
                </image>
                <clip>
                    <near>0.02</near>
                    <far>300</far>
                </clip>
                <noise>
                    <type>gaussian</type>
                    <mean>0.0</mean>
                    <stddev>0.007</stddev>
                </noise>
            </camera>
        </sensor>
    </gazebo>

    <!-- ........................... ROS2 CONTROL PLUGIN ................................... -->
    <gazebo>
        <plugin filename="ign_ros2_control-system" name="ign_ros2_control::IgnitionROS2ControlPlugin">
            <robot_param>robot_description</robot_param>
            <robot_param_node>robot_state_publisher</robot_param_node>
            <parameters>/home/prashun/ros2_ws/src/uno/config/controller.yaml</parameters>
        </plugin>
    </gazebo>
</robot>
